Workbook

Sheet 报关草单
A1: 中华人民共和国海关出口货物报关单
A2: 预录入编号： | J2: 申报口岸: | N2: 海关编号:
A3: 境内发货人 | C3: 深圳市亿莱沃实业有限公司 | H3: 出境关别 | K3: 出口日期 | N3: 46212 | Q3: 申报日期 | U3: 备案号
A4: 境外收货人 AEO： | C4: HK Kuntaikang Industrial Co., Limited | H4: 运输方式 | J4: 路运 | K4: 运输工具名称及航次号 | Q4: 提运单号
A5: 生产销售单位 | C5: =C3 -> 深圳市亿莱沃实业有限公司 | H5: 监管方式 | J5: 一般贸易 | K5: 征免性质 | N5: 一般征税 | Q5: 许可证号
A6: 合同协议号 | C6: YLW-20260709001 | H6: 贸易国(地区) | J6: 香港 | K6: 运抵国(地区) | N6: 德国 | Q6: 指运港 | U6: 离境口岸
A7: 包装种类 | C7: 纸箱 | F7: 件数 | G7: 15件 | I7: 毛重 | J7: 267千克 | K7: 净重 | L7: 224.82千克 | N7: 成交方式 | O7: FOB | Q7: 运费 | S7: 保费 | W7: 杂费
A8: 随附单证及编号
A9: 境外收货人完整显示：
A10: 标记唛码及备注：
A11: 特殊关系确认: | D11: 否 | E11: 价格影响确认： | H11: 否 | J11: 支付特许权使用费: | L11: 否 | N11: 自报自缴: | O11: 否 | Q11: 出口不填 | R11: 原产国/目的国/货源地未注明的项默认与提供的项相同
A12: 序号 | B12: 商品编码 | D12: 商检编码 | E12: 商品名称 | G12: 规格型号 | K12: 数量 | L12: 单位 | M12: 净重 | N12: 单价 | O12: 总价 | P12: 币制 | Q12: 原产国 | S12: 最终目的地 | V12: 境内货源地 | Y12: 照章征税 | Z12: 毛重 | AA12: 件数
A13: 1 | B13: 4008110000 | D13: FD-602-GY505 | E13: 隔音棉 | G13: 隔音棉 5MM 5米*40CM | K13: 4 | L13: 个 | M13: =1.35*4 -> 5.4 | N13: 7.17 | O13: =K13*N13 -> 28.68 | P13: USD | Q13: 中国 | S13: 德国 | V13: 广州 | Y13: 照章征税 | Z13: 17 | AA13: 1
A14: 2 | B14: 3926909790 | C14: 3926909790 | D14: FD-511-RM1M15 | E14: 橡胶垫 | F14: 橡胶垫 | G14: 黑色柳叶橡胶垫3MM厚度 1*1.5米 | K14: 1 | L14: 个 | M14: 5.005 | N14: 6.58337 | O14: =K14*N14 -> 6.58337 | P14: USD | Q14: 中国 | S14: 德国 | V14: 沧州 | Y14: 照章征税
A15: 3 | B15: 3926909790 | C15: 3926909790 | D15: FD-509-C2KG | E15: 硅胶干燥剂 | F15: 硅胶干燥剂 | G15: 桶装2KG 纯黄色干燥剂 | K15: 2 | L15: 个 | M15: 4 | N15: 7.04845 | O15: =K15*N15 -> 14.0969 | P15: USD | Q15: 中国 | S15: 德国 | V15: 深圳 | Y15: 照章征税
A16: 4 | B16: 4008110000 | C16: 4008110000 | D16: FD-602-GY505 | E16: 隔音棉 | F16: 隔音棉 | G16: 隔音棉 5MM 5米*40CM | K16: 4 | L16: 个 | M16: =4*1.35 -> 5.4 | N16: 7.17 | O16: =K16*N16 -> 28.68 | P16: USD | Q16: 中国 | S16: 德国 | V16: 广州 | Y16: 照章征税 | Z16: 18.2 | AA16: 2
A17: 5 | B17: 3926909790 | C17: 3926909790 | D17: FD-511-RM1M15 | E17: 橡胶垫 | F17: 橡胶垫 | G17: 黑色柳叶橡胶垫3MM厚度 1*1.5米 | K17: 1 | L17: 个 | M17: 5.005 | N17: 6.58337 | O17: =K17*N17 -> 6.58337 | P17: USD | Q17: 中国 | S17: 德国 | V17: 沧州 | Y17: 照章征税
A18: 6 | B18: 3926909790 | C18: 3926909790 | D18: FD-509-C2KG | E18: 硅胶干燥剂 | F18: 硅胶干燥剂 | G18: 桶装2KG 纯黄色干燥剂 | K18: 2 | L18: 个 | M18: 4 | N18: 7.04845 | O18: =K18*N18 -> 14.0969 | P18: USD | Q18: 中国 | S18: 德国 | V18: 深圳 | Y18: 照章征税
A19: 7 | B19: 4008110000 | C19: 4008110000 | D19: FD-602-GY505 | E19: 隔音棉 | F19: 隔音棉 | G19: 隔音棉 5MM 5米*40CM | K19: 4 | L19: 个 | M19: =4*1.35 -> 5.4 | N19: 7.17 | O19: =K19*N19 -> 28.68 | P19: USD | Q19: 中国 | S19: 德国 | V19: 广州 | Y19: 照章征税 | Z19: 18 | AA19: 3
A20: 8 | B20: 3926909790 | C20: 3926909790 | D20: FD-511-RM1M15 | E20: 橡胶垫 | F20: 橡胶垫 | G20: 黑色柳叶橡胶垫3MM厚度 1*1.5米 | K20: 1 | L20: 个 | M20: 5.005 | N20: 6.58337 | O20: =K20*N20 -> 6.58337 | P20: USD | Q20: 中国 | S20: 德国 | V20: 沧州 | Y20: 照章征税
A21: 9 | B21: 3926909790 | C21: 3926909790 | D21: FD-509-C2KG | E21: 硅胶干燥剂 | F21: 硅胶干燥剂 | G21: 桶装2KG 纯黄色干燥剂 | K21: 2 | L21: 个 | M21: 4 | N21: 7.04845 | O21: =K21*N21 -> 14.0969 | P21: USD | Q21: 中国 | S21: 德国 | V21: 深圳 | Y21: 照章征税
A22: 10 | B22: 4008110000 | C22: 4008110000 | D22: FD-602-GY505 | E22: 隔音棉 | F22: 隔音棉 | G22: 隔音棉 5MM 5米*40CM | K22: 3 | L22: 个 | M22: =+K22*1.35 -> 4.05 | N22: 7.17 | O22: =K22*N22 -> 21.51 | P22: USD | Q22: 中国 | S22: 德国 | V22: 广州 | Y22: 照章征税 | Z22: 15.3 | AA22: 4
A23: 11 | B23: 3926909790 | C23: 3926909790 | D23: FD-509-C2KG | E23: 硅胶干燥剂 | F23: 硅胶干燥剂 | G23: 桶装2KG 纯黄色干燥剂 | K23: 2 | L23: 个 | M23: 4 | N23: 7.04845 | O23: =K23*N23 -> 14.0969 | P23: USD | Q23: 中国 | S23: 德国 | V23: 深圳 | Y23: 照章征税
A24: 12 | B24: 3926909790 | C24: 3926909790 | D24: FD-509-C1KG | E24: 硅胶干燥剂 | F24: 硅胶干燥剂 | G24: 桶装1KG 纯黄色干燥剂 | K24: 2 | L24: 个 | M24: 2 | N24: 7.04845 | O24: =K24*N24 -> 14.0969 | P24: USD | Q24: 中国 | S24: 德国 | V24: 深圳 | Y24: 照章征税
A25: 13 | B25: 5601229000 | C25: 5601229000 | D25: FD-506-TCM | E25: 聚脂钎维填充物 | F25: 聚脂钎维填充物 | G25: 颗粒棉 1KG 尺寸37*25*10 | K25: 3 | L25: 个 | M25: 3 | N25: 3.83788 | O25: =K25*N25 -> 11.51364 | P25: USD | Q25: 中国 | S25: 德国 | V25: 东莞 | Y25: 照章征税
A26: 14 | B26: 4008110000 | C26: 4008110000 | D26: FD-602-GY505 | E26: 隔音棉 | F26: 隔音棉 | G26: 隔音棉 5MM 5米*40CM | K26: 2 | L26: 个 | M26: =+K26*1.35 -> 2.7 | N26: 7.17 | O26: =K26*N26 -> 14.34 | P26: USD | Q26: 中国 | S26: 德国 | V26: 广州 | Y26: 照章征税 | Z26: 16.6 | AA26: 5
A27: 15 | B27: 3926909790 | C27: 3926909790 | D27: FD-504-GZ516 | E27: 硅胶干燥剂 | F27: 硅胶干燥剂 | G27: 透明掺黄色（20%）干燥剂 50g 16包装 | K27: 2 | L27: 包 | M27: 1.6 | N27: 2.199 | O27: =K27*N27 -> 4.398 | P27: USD | Q27: 中国 | S27: 德国 | V27: 深圳 | Y27: 照章征税
A28: 16 | B28: 3926909790 | C28: 3926909790 | D28: FD-509-C2KG | E28: 硅胶干燥剂 | F28: 硅胶干燥剂 | G28: 桶装2KG 纯黄色干燥剂 | K28: 2 | L28: 个 | M28: 4 | N28: 7.04845 | O28: =K28*N28 -> 14.0969 | P28: USD | Q28: 中国 | S28: 德国 | V28: 深圳 | Y28: 照章征税
A29: 17 | B29: 8302490000 | C29: 8302490000 | D29: FD-601-FCDA | E29: 推拉杆 | F29: 推拉杆 | G29: 屋顶杆天窗开窗器管径2CM5节1.86M黑色 | K29: 6 | L29: 个 | M29: =+K29*0.5 -> 3 | N29: 5.14 | O29: =K29*N29 -> 30.84 | P29: USD | Q29: 中国 | S29: 德国 | V29: 惠州 | Y29: 照章征税
A30: 18 | B30: 5601229000 | C30: 5601229000 | D30: FD-506-TCM | E30: 聚脂钎维填充物 | F30: 聚脂钎维填充物 | G30: 颗粒棉 1KG 尺寸37*25*10 | K30: 3 | L30: 个 | M30: 3 | N30: 3.83788 | O30: =K30*N30 -> 11.51364 | P30: USD | Q30: 中国 | S30: 德国 | V30: 东莞 | Y30: 照章征税
A31: 19 | B31: 4008110000 | C31: 4008110000 | D31: FD-602-GY505 | E31: 隔音棉 | F31: 隔音棉 | G31: 隔音棉 5MM 5米*40CM | K31: 3 | L31: 个 | M31: =+K31*1.35 -> 4.05 | N31: 7.17 | O31: =K31*N31 -> 21.51 | P31: USD | Q31: 中国 | S31: 德国 | V31: 广州 | Y31: 照章征税 | Z31: 19 | AA31: 6
A32: 20 | B32: 3926909790 | C32: 3926909790 | D32: FD-504-GZ516 | E32: 硅胶干燥剂 | F32: 硅胶干燥剂 | G32: 透明掺黄色（20%）干燥剂 50g 16包装 | K32: 2 | L32: 包 | M32: 1.6 | N32: 2.199 | O32: =K32*N32 -> 4.398 | P32: USD | Q32: 中国 | S32: 德国 | V32: 深圳 | Y32: 照章征税
A33: 21 | B33: 3926909790 | C33: 3926909790 | D33: FD-509-C2KG | E33: 硅胶干燥剂 | F33: 硅胶干燥剂 | G33: 桶装2KG 纯黄色干燥剂 | K33: 4 | L33: 个 | M33: 8 | N33: 14.0969 | O33: =K33*N33 -> 56.3876 | P33: USD | Q33: 中国 | S33: 德国 | V33: 深圳 | Y33: 照章征税
A34: 22 | B34: 5601229000 | C34: 5601229000 | D34: FD-504-682 | E34: 聚脂钎维填充物 | F34: 聚脂钎维填充物 | G34: 过滤棉家纺棉170g 0.68m*2m*15mm | K34: 5 | L34: 个 | M34: =5*0.27 -> 1.35 | N34: 2.06088 | O34: =K34*N34 -> 10.3044 | P34: USD | Q34: 中国 | S34: 德国 | V34: 东莞 | Y34: 照章征税
A35: 23 | B35: 5601229000 | C35: 5601229000 | D35: FD-506-TCM | E35: 聚脂钎维填充物 | F35: 聚脂钎维填充物 | G35: 颗粒棉 1KG 尺寸37*25*10 | K35: 1 | L35: 个 | M35: 1 | N35: 3.83788 | O35: =K35*N35 -> 3.83788 | P35: USD | Q35: 中国 | S35: 德国 | V35: 东莞 | Y35: 照章征税
A36: 24 | B36: 3926909790 | C36: 3926909790 | D36: FD-504-GZ516 | E36: 硅胶干燥剂 | F36: 硅胶干燥剂 | G36: 透明掺黄色（20%）干燥剂 50g 16包装 | K36: 2 | L36: 包 | M36: 1.6 | N36: 2.199 | O36: =K36*N36 -> 4.398 | P36: USD | Q36: 中国 | S36: 德国 | V36: 深圳 | Y36: 照章征税 | Z36: 18.6 | AA36: 7
A37: 25 | B37: 3926909790 | C37: 3926909790 | D37: FD-509-C2KG | E37: 硅胶干燥剂 | F37: 硅胶干燥剂 | G37: 桶装2KG 纯黄色干燥剂 | K37: 2 | L37: 个 | M37: 4 | N37: 7.04845 | O37: =K37*N37 -> 14.0969 | P37: USD | Q37: 中国 | S37: 德国 | V37: 深圳 | Y37: 照章征税
A38: 26 | B38: 3926909790 | C38: 3926909790 | D38: FD-509-C1KG | E38: 硅胶干燥剂 | F38: 硅胶干燥剂 | G38: 桶装1KG 纯黄色干燥剂 | K38: 1 | L38: 个 | M38: 1 | N38: 3.525 | O38: =K38*N38 -> 3.525 | P38: USD | Q38: 中国 | S38: 德国 | V38: 深圳 | Y38: 照章征税
A39: 27 | B39: 8302490000 | C39: 8302490000 | D39: FD-601-FCDA | E39: 推拉杆 | F39: 推拉杆 | G39: 屋顶杆天窗开窗器管径2CM5节1.86M黑色 | K39: 5 | L39: 个 | M39: =+K39*0.5 -> 2.5 | N39: 5.14 | O39: =K39*N39 -> 25.7 | P39: USD | Q39: 中国 | S39: 德国 | V39: 惠州 | Y39: 照章征税
A40: 28 | B40: 5601229000 | C40: 5601229000 | D40: FD-504-682 | E40: 聚脂钎维填充物 | F40: 聚脂钎维填充物 | G40: 过滤棉家纺棉170g 0.68m*2m*15mm | K40: 3 | L40: 个 | M40: =3*0.27 -> 0.81 | N40: 2.06088 | O40: =K40*N40 -> 6.18264 | P40: USD | Q40: 中国 | S40: 德国 | V40: 东莞 | Y40: 照章征税
...

Sheet 合同
A1: 合 同 CONTRACT
A5: 卖 方: | C5: =报关草单!C3 -> 深圳市亿莱沃实业有限公司 | T5: 合同号码： | W5: =报关草单!C6 -> YLW-20260709001
A6: Sellers: | T6: Contract No：
A7: 地址： | C7: 深圳市龙华区龙华建辉路123号长田科技园2栋503号 | T7: 日 期： | W7: =报关草单!N3 -> 46212
A8: Address: | T8: Date:
A9: 电话 | D9: 18927405120 | H9: 电挂 | L9: 传真 | T9: 签约地点： | W9: 中国
A10: Telephone: | H10: Cable: | L10: Fax: | T10: Signed at：
A11: 买 方: | C11: =报关草单!C4 -> HK Kuntaikang Industrial Co., Limited
A12: Buyers:
A13: 地址： | C13: 香港屯門新安街 9 號堅基工業大廈 16 樓 D 室 R2 房
A14: Address:
A15: 电话： | H15: 电挂： | P15: 传真：
A16: Telephone: | H16: Cable: | P16: Fax:
A17: 经买卖双方确认根据下列条款订立本合同：
A18: This contract is made out by the Sellers and Buyers as per the following terms and conditions mutuilly confirmed:
A19: （1）货 物 名 称 及 规 格 | M19: （2）数 量及单位 | R19: (3)单 价(USD) | W19: (4)金 额（USD)
A20: Name of commodity and Specification | M20: Quantity | R20: Unit Price | W20: Amount
A21: 黑色柳叶橡胶垫3MM厚度 1*1.5米 | M21: 3 | P21: =报关草单!L13 -> 个 | R21: 6.58337 | W21: =M21*R21 -> 19.75011
A22: 透明掺黄色（20%）干燥剂 吸水后变绿色 50g 16包装 | B22: 透明掺黄色（20%）干燥剂 吸水后变绿色 50g 16包装 | C22: 透明掺黄色（20%）干燥剂 吸水后变绿色 50g 16包装 | D22: 透明掺黄色（20%）干燥剂 吸水后变绿色 50g 16包装 | E22: 透明掺黄色（20%）干燥剂 吸水后变绿色 50g 16包装 | F22: 透明掺黄色（20%）干燥剂 吸水后变绿色 50g 16包装 | G22: 透明掺黄色（20%）干燥剂 吸水后变绿色 50g 16包装 | H22: 透明掺黄色（20%）干燥剂 吸水后变绿色 50g 16包装 | I22: 透明掺黄色（20%）干燥剂 吸水后变绿色 50g 16包装 | J22: 透明掺黄色（20%）干燥剂 吸水后变绿色 50g 16包装 | K22: 透明掺黄色（20%）干燥剂 吸水后变绿色 50g 16包装 | L22: 透明掺黄色（20%）干燥剂 吸水后变绿色 50g 16包装 | M22: 20 | N22: 40 | O22: 40 | P22: 包 | R22: 2.24 | W22: =M22*R22 -> 44.8
A23: 过滤棉家纺棉170g 0.68m*2m*15mm | B23: 过滤棉家纺棉170g 0.68m*2m*15mm | C23: 过滤棉家纺棉170g 0.68m*2m*15mm | D23: 过滤棉家纺棉170g 0.68m*2m*15mm | E23: 过滤棉家纺棉170g 0.68m*2m*15mm | F23: 过滤棉家纺棉170g 0.68m*2m*15mm | G23: 过滤棉家纺棉170g 0.68m*2m*15mm | H23: 过滤棉家纺棉170g 0.68m*2m*15mm | I23: 过滤棉家纺棉170g 0.68m*2m*15mm | J23: 过滤棉家纺棉170g 0.68m*2m*15mm | K23: 过滤棉家纺棉170g 0.68m*2m*15mm | L23: 过滤棉家纺棉170g 0.68m*2m*15mm | M23: 30 | N23: 41 | O23: 41 | P23: 个 | R23: 2.06088 | W23: =M23*R23 -> 61.8264
A24: 颗粒棉 1KG 尺寸37*25*10 | B24: 颗粒棉 1KG 尺寸37*25*10 | C24: 颗粒棉 1KG 尺寸37*25*10 | D24: 颗粒棉 1KG 尺寸37*25*10 | E24: 颗粒棉 1KG 尺寸37*25*10 | F24: 颗粒棉 1KG 尺寸37*25*10 | G24: 颗粒棉 1KG 尺寸37*25*10 | H24: 颗粒棉 1KG 尺寸37*25*10 | I24: 颗粒棉 1KG 尺寸37*25*10 | J24: 颗粒棉 1KG 尺寸37*25*10 | K24: 颗粒棉 1KG 尺寸37*25*10 | L24: 颗粒棉 1KG 尺寸37*25*10 | M24: 58 | N24: 103 | O24: 103 | P24: =报关草单!L17 -> 个 | R24: 3.8379 | W24: =M24*R24 -> 222.5982
A25: 隔音棉 5MM 5米*40CM | B25: 隔音棉 5mm厚度 0.4M*10M | C25: 隔音棉 5mm厚度 0.4M*10M | D25: 隔音棉 5mm厚度 0.4M*10M | E25: 隔音棉 5mm厚度 0.4M*10M | F25: 隔音棉 5mm厚度 0.4M*10M | G25: 隔音棉 5mm厚度 0.4M*10M | H25: 隔音棉 5mm厚度 0.4M*10M | I25: 隔音棉 5mm厚度 0.4M*10M | J25: 隔音棉 5mm厚度 0.4M*10M | K25: 隔音棉 5mm厚度 0.4M*10M | L25: 隔音棉 5mm厚度 0.4M*10M | M25: 22 | N25: 30 | O25: 30 | P25: =报关草单!L18 -> 个 | R25: 7.17 | W25: =M25*R25 -> 157.74
A26: 桶装2KG 纯黄色干燥剂 | B26: 桶装2KG 纯黄色干燥剂 | C26: 桶装2KG 纯黄色干燥剂 | D26: 桶装2KG 纯黄色干燥剂 | E26: 桶装2KG 纯黄色干燥剂 | F26: 桶装2KG 纯黄色干燥剂 | G26: 桶装2KG 纯黄色干燥剂 | H26: 桶装2KG 纯黄色干燥剂 | I26: 桶装2KG 纯黄色干燥剂 | J26: 桶装2KG 纯黄色干燥剂 | K26: 桶装2KG 纯黄色干燥剂 | L26: 桶装2KG 纯黄色干燥剂 | M26: 31 | N26: 27 | O26: 27 | P26: 桶 | R26: 8.159 | W26: =M26*R26 -> 252.929
A27: 桶装1KG 纯黄色干燥剂 | M27: 10 | P27: 桶 | R27: 3.525 | W27: =M27*R27 -> 35.25
A28: 屋顶杆天窗开窗器管径2CM5节1.86M黑色 | M28: 52 | P28: 个 | R28: 5.14 | W28: =M28*R28 -> 267.28
M29: =SUM(M21:M28) -> 226 | W29: =SUM(W21:AB28) -> 1062.1737
A31: 数量及总值允许有 2%的增减。 | S31: 总 值：USD | W31: =W29 -> 1062.1737
A32: %more or less both in amount and quantity allowed. | S32: Total Amount:
A33: (5)合同总值： 美元壹仟陆拾贰圆壹拾柒
A34: Total Value in Word:
A35: (6)包装及唛头： | G35: =[1]报关资料录入!S13 -> 0
A36: Packing and shipping Marks:
A37: (7)装运期： | F37: =[1]报关资料录入!AB10 -> 0
A38: Time of Shipment:
A39: (8)装运口岸和目的地 | G39: 中国 | P39: 准许分批与转船。
A40: Loading Port & Destination:From | O40: with transshipment and partial shipments allowed.
A41: (9)保险:由卖方按发票全部金额110%投保至 | N41: 为止的 | S41: 险。按中国铁路运输保险条款办理。
A42: Insurance:To be effectted by Seller for 110%offull invoice value covering | Y42: up
A43: only,subject to C.I.C.
A44: (10)付款条件：
...

Sheet 发票
A1: 发 票 INVOICE
R7: 合同号: | T7: =报关草单!C6 -> YLW-20260709001
R8: NO:
A9: 卖 方: Sellers: | F9: =报关草单!C3 -> 深圳市亿莱沃实业有限公司 | R9: 日 期: | T9: =报关草单!N3 -> 46212
A10: Sold to Massers: | R10: DATE:
A13: 标记号码 | D13: 货物名称 | N13: 数 量 | Q13: 单位 | S13: 单价(USD) | W13: 总金额(USD)
A14: Mark ＆ No | D14: Description | N14: Quantity | Q14: Unit | S14: Unit price | W14: Amount
A15: =报关草单!A13 -> 1 | D15: =+合同!A21 -> 黑色柳叶橡胶垫3MM厚度 1*1.5米 | N15: 3 | Q15: 个 | S15: =+合同!R21 -> 6.58337 | W15: =+合同!W21 -> 19.75011
A16: =报关草单!A14 -> 2 | D16: =+合同!A22 -> 透明掺黄色（20%）干燥剂 吸水后变绿色 50g 16包装 | N16: 20 | O16: 40 | P16: 40 | Q16: 包 | S16: =+合同!R22 -> 2.24 | W16: =S16*N16 -> 44.8
A17: =报关草单!A15 -> 3 | D17: =+合同!A23 -> 过滤棉家纺棉170g 0.68m*2m*15mm | N17: 30 | O17: 41 | P17: 41 | Q17: 个 | S17: =+合同!R23 -> 2.06088 | W17: =S17*N17 -> 61.8264
A18: =报关草单!A16 -> 4 | D18: =+合同!A24 -> 颗粒棉 1KG 尺寸37*25*10 | N18: 58 | O18: 103 | P18: 103 | Q18: 个 | S18: =+合同!R24 -> 3.8379 | W18: =S18*N18 -> 222.5982
A19: =报关草单!A17 -> 5 | D19: =+合同!A25 -> 隔音棉 5MM 5米*40CM | N19: 22 | O19: 30 | P19: 30 | Q19: 个 | S19: =+合同!R25 -> 7.17 | W19: =S19*N19 -> 157.74
A20: =报关草单!A18 -> 6 | D20: =+合同!A26 -> 桶装2KG 纯黄色干燥剂 | N20: 31 | O20: 40 | P20: 40 | Q20: 个 | S20: =+合同!R26 -> 8.159 | W20: =S20*N20 -> 252.929
A21: =报关草单!A19 -> 7 | D21: =+合同!A27 -> 桶装1KG 纯黄色干燥剂 | N21: 10 | O21: 27 | P21: 27 | Q21: 桶 | S21: =+合同!R27 -> 3.525 | W21: =S21*N21 -> 35.25
A22: =报关草单!A20 -> 8 | D22: =+合同!A28 -> 屋顶杆天窗开窗器管径2CM5节1.86M黑色 | N22: 52 | Q22: 根 | S22: =+合同!R28 -> 5.14 | W22: =S22*N22 -> 267.28
N23: =SUM(N15:N22) -> 226 | S23: =[1]报关资料录入!U50 -> 总合计: | W23: =SUM(W15:W22) -> 1062.1737
B25: 唛头
B26: Marks

Sheet 装箱单
A1: 装 箱 单 PACKING LIST
S2: 日 期： | V2: =报关草单!N3 -> 46212
S3: Date:
S4: 发票编号：
S5: Invoice NO:
A6: 卖 方: | D6: =报关草单!C3 -> 深圳市亿莱沃实业有限公司 | S6: 合 同 号： | V6: =报关草单!C6 -> YLW-20260709001
A7: Sellers： | S7: Contract No:
A8: 船名： | S8: 付 款 条 件：
A9: Shipped by： | S9: Termsof Payment:
A10: 箱 号 | C10: 货物名称及规格 | N10: 总箱数(件) | Q10: 总数量 | U10: 总毛重(kg) | X10: 总净重(kg)
A11: Ctn.NO. | C11: Description | N11: Ge.Crate | Q11: Ge.Quantity | U11: G.W.:(kg) | X11: N.W.:(kg)
A12: =报关草单!A13 -> 1 | C12: =报关草单!E13 -> 隔音棉 | N12: =报关草单!AA13 -> 1 | Q12: =报关草单!K13 -> 4 | S12: =报关草单!L13 -> 个 | U12: =报关草单!Z13 -> 17 | X12: =1.35*4 -> 5.4
A13: =报关草单!A14 -> 2 | C13: =报关草单!E14 -> 橡胶垫 | N13: =报关草单!AA14 -> 0 | Q13: =报关草单!K14 -> 1 | S13: =报关草单!L14 -> 个 | U13: =报关草单!Z14 -> 0 | X13: =报关草单!M14 -> 5.005
A14: =报关草单!A15 -> 3 | C14: =报关草单!E15 -> 硅胶干燥剂 | N14: =报关草单!AA15 -> 0 | Q14: =报关草单!K15 -> 2 | S14: =报关草单!L15 -> 个 | U14: =报关草单!Z15 -> 0 | X14: =报关草单!M15 -> 4
A15: =报关草单!A16 -> 4 | C15: =报关草单!E16 -> 隔音棉 | N15: =报关草单!AA16 -> 2 | Q15: =报关草单!K16 -> 4 | S15: =报关草单!L16 -> 个 | U15: =报关草单!Z16 -> 18.2 | X15: =报关草单!M16 -> 5.4
A16: =报关草单!A17 -> 5 | C16: =报关草单!E17 -> 橡胶垫 | N16: =报关草单!AA17 -> 0 | Q16: =报关草单!K17 -> 1 | S16: =报关草单!L17 -> 个 | U16: =报关草单!Z17 -> 0 | X16: =报关草单!M17 -> 5.005
A17: =报关草单!A18 -> 6 | C17: =报关草单!E18 -> 硅胶干燥剂 | N17: =报关草单!AA18 -> 0 | Q17: =报关草单!K18 -> 2 | S17: =报关草单!L18 -> 个 | U17: =报关草单!Z18 -> 0 | X17: =报关草单!M18 -> 4
A18: =报关草单!A19 -> 7 | C18: =报关草单!E19 -> 隔音棉 | N18: =报关草单!AA19 -> 3 | Q18: =报关草单!K19 -> 4 | S18: =报关草单!L19 -> 个 | U18: =报关草单!Z19 -> 18 | X18: =报关草单!M19 -> 5.4
A19: =报关草单!A20 -> 8 | C19: =报关草单!E20 -> 橡胶垫 | N19: =报关草单!AA20 -> 0 | Q19: =报关草单!K20 -> 1 | S19: =报关草单!L20 -> 个 | U19: =报关草单!Z20 -> 0 | X19: =报关草单!M20 -> 5.005
A20: =报关草单!A21 -> 9 | C20: =报关草单!E21 -> 硅胶干燥剂 | N20: =报关草单!AA21 -> 0 | Q20: =报关草单!K21 -> 2 | S20: =报关草单!L21 -> 个 | U20: =报关草单!Z21 -> 0 | X20: =报关草单!M21 -> 4
A21: =报关草单!A22 -> 10 | C21: =报关草单!E22 -> 隔音棉 | N21: =报关草单!AA22 -> 4 | Q21: =报关草单!K22 -> 3 | S21: =报关草单!L22 -> 个 | U21: =报关草单!Z22 -> 15.3 | X21: =报关草单!M22 -> 4.05
A22: =报关草单!A23 -> 11 | C22: =报关草单!E23 -> 硅胶干燥剂 | N22: =报关草单!AA23 -> 0 | Q22: =报关草单!K23 -> 2 | S22: =报关草单!L23 -> 个 | U22: =报关草单!Z23 -> 0 | X22: =报关草单!M23 -> 4
A23: =报关草单!A24 -> 12 | C23: =报关草单!E24 -> 硅胶干燥剂 | N23: =报关草单!AA24 -> 0 | Q23: =报关草单!K24 -> 2 | S23: =报关草单!L24 -> 个 | U23: =报关草单!Z24 -> 0 | X23: =报关草单!M24 -> 2
A24: =报关草单!A25 -> 13 | C24: =报关草单!E25 -> 聚脂钎维填充物 | N24: =报关草单!AA25 -> 0 | Q24: =报关草单!K25 -> 3 | S24: =报关草单!L25 -> 个 | U24: =报关草单!Z25 -> 0 | X24: =报关草单!M25 -> 3
... A52: =报关草单!A53 -> 41 | C52: =报关草单!E53 -> 硅胶干燥剂 | N52: =报关草单!AA53 -> 0 | Q52: =报关草单!K53 -> 3 | S52: =报关草单!L53 -> 个 | U52: =报关草单!Z53 -> 0 | X52: =报关草单!M53 -> 6
A53: =报关草单!A54 -> 42 | C53: =报关草单!E54 -> 推拉杆 | N53: =报关草单!AA54 -> 0 | Q53: =报关草单!K54 -> 6 | S53: =报关草单!L75 -> 个 | U53: =报关草单!Z54 -> 0 | X53: =报关草单!M54 -> 3
A54: =报关草单!A55 -> 43 | C54: =报关草单!E55 -> 聚脂钎维填充物 | N54: =报关草单!AA55 -> 0 | Q54: =报关草单!K55 -> 1 | S54: =报关草单!L76 -> 个 | U54: =报关草单!Z55 -> 0 | X54: =报关草单!M55 -> 0.27
A55: =报关草单!A56 -> 44 | C55: =报关草单!E56 -> 聚脂钎维填充物 | N55: =报关草单!AA56 -> 0 | Q55: =报关草单!K56 -> 3 | S55: =报关草单!L77 -> 个 | U55: =报关草单!Z56 -> 0 | X55: =报关草单!M56 -> 3
A56: =报关草单!A57 -> 45 | C56: =报关草单!E57 -> 硅胶干燥剂 | N56: =报关草单!AA57 -> 11 | Q56: =报关草单!K57 -> 2 | S56: =报关草单!L78 -> 个 | U56: =报关草单!Z57 -> 18.6 | X56: =报关草单!M57 -> 1.6
A57: =报关草单!A58 -> 46 | C57: =报关草单!E58 -> 硅胶干燥剂 | N57: =报关草单!AA58 -> 0 | Q57: =报关草单!K58 -> 2 | S57: =报关草单!L79 -> 包 | U57: =报关草单!Z58 -> 0 | X57: =报关草单!M58 -> 4
A58: =报关草单!A59 -> 47 | C58: =报关草单!E59 -> 硅胶干燥剂 | N58: =报关草单!AA59 -> 0 | Q58: =报关草单!K59 -> 1 | S58: =报关草单!L80 -> 个 | U58: =报关草单!Z59 -> 0 | X58: =报关草单!M59 -> 1
A59: =报关草单!A60 -> 48 | C59: =报关草单!E60 -> 推拉杆 | N59: =报关草单!AA60 -> 0 | Q59: =报关草单!K60 -> 5 | S59: =报关草单!L81 -> 个 | U59: =报关草单!Z60 -> 0 | X59: =报关草单!M60 -> 2.5
A60: =报关草单!A61 -> 49 | C60: =报关草单!E61 -> 聚脂钎维填充物 | N60: =报关草单!AA61 -> 0 | Q60: =报关草单!K61 -> 3 | S60: =报关草单!L82 -> 个 | U60: =报关草单!Z61 -> 0 | X60: =报关草单!M61 -> 0.81
A61: =报关草单!A62 -> 50 | C61: =报关草单!E62 -> 聚脂钎维填充物 | N61: =报关草单!AA62 -> 0 | Q61: =报关草单!K62 -> 6 | S61: =报关草单!L83 -> 个 | U61: =报关草单!Z62 -> 0 | X61: =报关草单!M62 -> 6
A62: =报关草单!A63 -> 51 | C62: =报关草单!E63 -> 硅胶干燥剂 | N62: =报关草单!AA63 -> 12 | Q62: =报关草单!K63 -> 2 | S62: =报关草单!L84 -> 0 | U62: =报关草单!Z63 -> 17.6 | X62: =报关草单!M63 -> 1.6
A63: =报关草单!A64 -> 52 | C63: =报关草单!E64 -> 硅胶干燥剂 | N63: =报关草单!AA64 -> 0 | Q63: =报关草单!K64 -> 2 | S63: =报关草单!L85 -> 0 | U63: =报关草单!Z64 -> 0 | X63: =报关草单!M64 -> 4
A64: =报关草单!A65 -> 53 | C64: =报关草单!E65 -> 推拉杆 | N64: =报关草单!AA65 -> 0 | Q64: =报关草单!K65 -> 5 | S64: =报关草单!L86 -> 0 | U64: =报关草单!Z65 -> 0 | X64: =报关草单!M65 -> 2.5
... A82: =报关草单!A83 -> 71 | C82: =报关草单!E83 -> 聚脂钎维填充物 | N82: =报关草单!AA83 -> 0 | Q82: =报关草单!K83 -> 6 | S82: =报关草单!L104 -> 0 | U82: =报关草单!Z83 -> 0 | X82: =报关草单!M83 -> 6
A83: 合计: | N83: 15 | Q83: =SUM(Q12:Q82) -> 226 | U83: =SUM(U12:W82) -> 267 | X83: =SUM(X12:AA82) -> 224.815
A85: 唛头
...

Sheet 报关草单合并
A1: 中华人民共和国海关出口货物报关单
A2: 预录入编号： | J2: 申报口岸: | P2: 海关编号:
A3: 境内发货人 | C3: 深圳市亿莱沃实业有限公司 | H3: 出境关别 | M3: 出口日期 | P3: 46212 | S3: 申报日期 | W3: 备案号
A4: 境外收货人 AEO： | C4: HK Kuntaikang Industrial Co., Limited | H4: 运输方式 | J4: 铁路运 | M4: 运输工具名称及航次号 | S4: 提运单号
A5: 生产销售单位 | C5: =C3 -> 深圳市亿莱沃实业有限公司 | H5: 监管方式 | J5: 一般贸易 | M5: 征免性质 | P5: 一般征税 | S5: 许可证号
A6: 合同协议号 | C6: =+报关草单!C6 -> YLW-20260709001 | H6: 贸易国(地区) | J6: 香港 | M6: 运抵国(地区) | P6: 德国 | S6: 指运港 | W6: 离境口岸
A7: 包装种类 | C7: 纸箱 | F7: 件数 | G7: 15件 | I7: 毛重 | J7: 267千克 | M7: 净重 | N7: 224.82千克 | P7: 成交方式 | Q7: FOB | S7: 运费 | U7: 保费 | Y7: 杂费
A8: 随附单证及编号
A9: 境外收货人完整显示：
A10: 标记唛码及备注：
A11: 特殊关系确认: | D11: 否 | E11: 价格影响确认： | H11: 否 | J11: 支付特许权使用费: | N11: 否 | P11: 自报自缴: | Q11: 否 | S11: 出口不填 | T11: 原产国/目的国/货源地未注明的项默认与提供的项相同
A12: 序号 | B12: 商品编码 | D12: 商检编码 | E12: 商品名称 | G12: 规格型号 | K12: 材质 | L12: 用途 | M12: 数量 | N12: 单位 | O12: 净重 | P12: 单价 | Q12: 总价 | R12: 币制 | S12: 原产国 | U12: 最终目的地 | X12: 境内货源地 | AA12: 照章征税 | AB12: 毛重 | AC12: 件数
A13: 1 | B13: 4008210000 | E13: 橡胶垫 | G13: =+发票!D15 -> 黑色柳叶橡胶垫3MM厚度 1*1.5米 | K13: 外观：片 材质：橡胶 ，硫化，无品牌 | L13: 汽配 | M13: 3 | N13: 个 | O13: =3*5.005 -> 15.015 | P13: =+发票!S15 -> 6.58337 | Q13: =M13*P13 -> 19.75011 | R13: USD | S13: 中国 | U13: 德国 | X13: 沧州 | AA13: 照章征税 | AC13: 27
A14: 2 | B14: 3824999999 | C14: 8302490099 | E14: 硅胶干燥剂 | F14: 推拉杆 | G14: =+发票!D16 -> 透明掺黄色（20%）干燥剂 吸水后变绿色 50g 16包装 | K14: 硅胶 | L14: 除湿 | M14: 20 | N14: 包 | O14: =20*800/1000 -> 16 | P14: =+发票!S16 -> 2.24 | Q14: =M14*P14 -> 44.8 | R14: USD | S14: 中国 | U14: 德国 | X14: 深圳 | AA14: 照章征税
A15: 3 | B15: 5601229000 | C15: 7616999099 | E15: 聚脂钎维填充物 | F15: 软管 | G15: =+发票!D17 -> 过滤棉家纺棉170g 0.68m*2m*15mm | K15: 涤纶纤维 | L15: 过滤 | M15: 30 | N15: 个 | O15: =30*0.27 -> 8.1 | P15: =+发票!S17 -> 2.06088 | Q15: =M15*P15 -> 61.8264 | R15: USD | S15: 中国 | U15: 德国 | X15: 东莞 | AA15: 照章征税
A16: 4 | B16: 5601229000 | C16: 7616999099 | E16: 聚脂钎维填充物 | F16: 软管 | G16: =+发票!D18 -> 颗粒棉 1KG 尺寸37*25*10 | K16: 涤纶纤维 | L16: 填充 | M16: 58 | N16: 个 | O16: 58 | P16: =+发票!S18 -> 3.8379 | Q16: =M16*P16 -> 222.5982 | R16: USD | S16: 中国 | U16: 德国 | X16: 东莞 | AA16: 照章征税
A17: 5 | B17: 4008110000 | C17: 3926909790 | E17: 隔音棉 | F17: 橡胶垫 | G17: =+发票!D19 -> 隔音棉 5MM 5米*40CM | K17: 外观：片，材质：橡胶，无硫化 | L17: 隔音 | M17: 22 | N17: 个 | O17: =22*1.35 -> 29.7 | P17: =+发票!S19 -> 7.17 | Q17: =M17*P17 -> 157.74 | R17: USD | S17: 中国 | U17: 德国 | X17: 广州 | AA17: 照章征税
A18: 6 | B18: 3824999999 | C18: 8302490099 | E18: 硅胶干燥剂 | F18: 推拉杆 | G18: =+发票!D20 -> 桶装2KG 纯黄色干燥剂 | K18: 硅胶 | L18: 纺织 | M18: 31 | N18: 桶 | O18: 62 | P18: =+发票!S20 -> 8.159 | Q18: =M18*P18 -> 252.929 | R18: USD | S18: 中国 | U18: 德国 | X18: 深圳 | AA18: 照章征税
A19: 7 | B19: 3824999999 | C19: 8302490099 | E19: 硅胶干燥剂 | G19: =+发票!D21 -> 桶装1KG 纯黄色干燥剂 | K19: 硅胶 | L19: 除湿 | M19: 10 | N19: 桶 | O19: 10 | P19: =+发票!S21 -> 3.525 | Q19: =M19*P19 -> 35.25 | R19: USD | S19: 中国 | U19: 德国 | X19: 深圳 | AA19: 照章征税
B20: 8302490000 | E20: 推拉杆 | G20: =+发票!D22 -> 屋顶杆天窗开窗器管径2CM5节1.86M黑色 | K20: 不锈钢 | L20: 家具 | M20: 52 | N20: 根 | O20: =52*500/1000 -> 26 | P20: 5.14 | Q20: =M20*P20 -> 267.28 | R20: USD | S20: 中国 | U20: 德国 | X20: 惠州 | AA20: 照章征税
E21: 合计 | M21: =SUM(M13:M20) -> 226 | N21: 净重 | O21: =SUM(O13:O20) -> 224.815 | P21: 金额 | Q21: =SUM(Q13:Q20) -> 1062.1737 | R21: USD | AB21: 422.9 | AC21: 27
